try {
    hello;
} catch (error) {
    console.log(error.message);
    hey;
}
finally{
    console.log("Inside Try block");
}